<?xml version="1.0"?> 
<robot name="robot_base">

    <link name="base_footprint">
      <visual>
        <geometry>
           <box size="0.001 0.001 0.001" />
        </geometry>
      </visual>
    </link>

    <link name="base_link">
        <visual>
            <geometry>
                <box size="0.25 .16 .05"/>
            </geometry>
            <origin rpy="0 0 0" xyz="0 0 0"/>
            <material name="blue">
                <color rgba="0 0.5 0.8 1"/>
            </material>
        </visual>
    </link>

     <joint name="base_link2base_footprint" type="fixed">
      <parent link="base_footprint" />
      <child link="base_link" />
      <origin xyz="0 0 0.03" />
    </joint>
ode
    <link name="left_front_wheel">  
        <visual>  
            <geometry>  
                <cylinder length=".02" radius="0.025"/>  
            </geometry>  
            <material name="black">  
                <color rgba="0 0 0 1"/>  
            </material>  
        </visual>  
    </link>  
    
    <joint name="left_front_wheel_joint" type="continuous">  
        <axis xyz="0 0 1"/>  
        <parent link="base_link"/>  
        <child link="left_front_wheel"/>  
        <origin rpy="1.57075 0 0" xyz="0.1 0.08 -0.03"/>  
    </joint>  
    
    <link name="right_front_wheel">  
    <visual>  
        <geometry>  
            <cylinder length=".02" radius="0.025"/>  
        </geometry>  
        <material name="black">  
            <color rgba="0 0 0 1"/>  
        </material>  
    </visual>  
    </link>  
    
    <joint name="right_front_wheel_joint" type="continuous">  
        <axis xyz="0 0 1"/>  
        <parent link="base_link"/>  
        <child link="right_front_wheel"/>  
        <origin rpy="1.57075 0 0" xyz="0.1 -0.08 -0.03"/>  
    </joint>  
    
    <link name="left_back_wheel">  
        <visual>  
            <geometry>  
                <cylinder length=".02" radius="0.025"/>  
            </geometry>  
            <material name="black">  
                <color rgba="0 0 0 1"/>  
            </material>  
        </visual>  
    </link>
    
    <joint name="left_back_wheel_joint" type="continuous">  
        <axis xyz="0 0 1"/>  
        <parent link="base_link"/>  
        <child link="left_back_wheel"/>  
        <origin rpy="1.57075 0 0" xyz="-0.1 0.08 -0.03"/>  
    </joint>  
    
    <link name="right_back_wheel">  
        <visual>  
            <geometry>  
                <cylinder length=".02" radius="0.025"/>  
            </geometry>  
            <material name="black">  
                <color rgba="0 0 0 1"/>  
            </material>  
        </visual>  
    </link>  
    
    <joint name="right_back_wheel_joint" type="continuous">  
        <axis xyz="0 0 1"/>  
        <parent link="base_link"/>  
        <child link="right_back_wheel"/>  
        <origin rpy="1.57075 0 0" xyz="-0.1 -0.08 -0.03"/>  
    </joint>   
</robot>
